Traceback (most recent call last):
  File "/Users/ralf/Library/Mobile Documents/com~apple~CloudDocs/Kurse/FDAML/.venv/lib/python3.12/site-packages/nbclient/client.py", line 782, in _async_poll_for_reply
    msg = await ensure_async(self.kc.shell_channel.get_msg(timeout=new_timeout))
          ^^^^^^^^^^^^^^^^^^^^^^^^^^^^^^^^^^^^^^^^^^^^^^^^^^^^^^^^^^^^^^^^^^^^^^
  File "/Users/ralf/Library/Mobile Documents/com~apple~CloudDocs/Kurse/FDAML/.venv/lib/python3.12/site-packages/jupyter_core/utils/__init__.py", line 198, in ensure_async
    result = await obj
             ^^^^^^^^^
  File "/Users/ralf/Library/Mobile Documents/com~apple~CloudDocs/Kurse/FDAML/.venv/lib/python3.12/site-packages/jupyter_client/channels.py", line 315, in get_msg
    raise Empty
_queue.Empty

During handling of the above exception, another exception occurred:

Traceback (most recent call last):
  File "/Users/ralf/Library/Mobile Documents/com~apple~CloudDocs/Kurse/FDAML/.venv/lib/python3.12/site-packages/jupyter_cache/executors/utils.py", line 58, in single_nb_execution
    executenb(
  File "/Users/ralf/Library/Mobile Documents/com~apple~CloudDocs/Kurse/FDAML/.venv/lib/python3.12/site-packages/nbclient/client.py", line 1314, in execute
    return NotebookClient(nb=nb, resources=resources, km=km, **kwargs).execute()
           ^^^^^^^^^^^^^^^^^^^^^^^^^^^^^^^^^^^^^^^^^^^^^^^^^^^^^^^^^^^^^^^^^^^^^
  File "/Users/ralf/Library/Mobile Documents/com~apple~CloudDocs/Kurse/FDAML/.venv/lib/python3.12/site-packages/jupyter_core/utils/__init__.py", line 165, in wrapped
    return loop.run_until_complete(inner)
           ^^^^^^^^^^^^^^^^^^^^^^^^^^^^^^
  File "/opt/homebrew/Cellar/python@3.12/3.12.3/Frameworks/Python.framework/Versions/3.12/lib/python3.12/asyncio/base_events.py", line 687, in run_until_complete
    return future.result()
           ^^^^^^^^^^^^^^^
  File "/Users/ralf/Library/Mobile Documents/com~apple~CloudDocs/Kurse/FDAML/.venv/lib/python3.12/site-packages/nbclient/client.py", line 709, in async_execute
    await self.async_execute_cell(
  File "/Users/ralf/Library/Mobile Documents/com~apple~CloudDocs/Kurse/FDAML/.venv/lib/python3.12/site-packages/nbclient/client.py", line 1005, in async_execute_cell
    exec_reply = await self.task_poll_for_reply
                 ^^^^^^^^^^^^^^^^^^^^^^^^^^^^^^
  File "/Users/ralf/Library/Mobile Documents/com~apple~CloudDocs/Kurse/FDAML/.venv/lib/python3.12/site-packages/nbclient/client.py", line 806, in _async_poll_for_reply
    error_on_timeout_execute_reply = await self._async_handle_timeout(timeout, cell)
                                     ^^^^^^^^^^^^^^^^^^^^^^^^^^^^^^^^^^^^^^^^^^^^^^^
  File "/Users/ralf/Library/Mobile Documents/com~apple~CloudDocs/Kurse/FDAML/.venv/lib/python3.12/site-packages/nbclient/client.py", line 856, in _async_handle_timeout
    raise CellTimeoutError.error_from_timeout_and_cell(
nbclient.exceptions.CellTimeoutError: A cell timed out while it was being executed, after 30 seconds.
The message was: Cell execution timed out.
Here is a preview of the cell contents:
-------------------
['from sklearn.preprocessing import StandardScaler', 'from sklearn.cluster import KMeans', 'from sklearn.metrics import silhouette_samples', '', '']
...
['    for i in range(n_clusters):', '        pca_loadings_cluster = pca_loadings_df[pca_loadings_df.cluster_labels == i]', '        pca_loadings_tickers = pca_loadings_cluster.index[pca_loadings_cluster.silhouette_samples.rank(method = "first", ascending=False) <= pf_sizes[i]].tolist()', '        pca_loadings_df.loc[pca_loadings_tickers, "pf_labels"] = i', '        cluster_returns.loc[holding_data.index, f"cluster_pf_{i}"] = holding_data.loc[:, pca_loadings_df[pca_loadings_df.pf_labels == i].index.tolist()].mean(axis = 1)']
-------------------

